Workbook

Sheet Summary
A1: Festival Manager: economy summary
A2: Player type: | B2: =Inputs!B5 -> Average
A4: # | B4: Festival | C4: Spend (£) | D4: Income (£) | E4: Profit (£) | F4: Profit % | G4: Customer satisfaction | H4: Band satisfaction | I4: Stars | J4: Result | K4: Promoter advance (£) | L4: Cash at end (£)
A5: =Model!A5 -> 1 | B5: =Model!B5 -> Village Green | C5: =Model!U5 -> 14062.594 | D5: =Model!AL5 -> 15259.524 | E5: =Model!AM5 -> 528.17947 | F5: =Model!AN5 -> 0.037559177 | G5: =Model!AR5 -> 0.6715 | H5: =Model!AS5 -> 0.72169048 | I5: =Model!AW5 -> 2 | J5: =Model!AX5 -> Pass | K5: =Model!I5 -> 0 | L5: =Model!AZ5 -> 20528.179
A6: =Model!A6 -> 2 | B6: =Model!B6 -> The Local Field | C6: =Model!U6 -> 49496.117 | D6: =Model!AL6 -> 55073.238 | E6: =Model!AM6 -> 3720.8712 | F6: =Model!AN6 -> 0.075175014 | G6: =Model!AR6 -> 0.67632591 | H6: =Model!AS6 -> 0.72169301 | I6: =Model!AW6 -> 2 | J6: =Model!AX6 -> Pass | K6: =Model!I6 -> 28971.821 | L6: =Model!AZ6 -> 20772.432
A7: =Model!A7 -> 3 | B7: =Model!B7 -> Two Stages | C7: =Model!U7 -> 131989.64 | D7: =Model!AL7 -> 149858.39 | E7: =Model!AM7 -> 12858.743 | F7: =Model!AN7 -> 0.097422361 | G7: =Model!AR7 -> 0.6936273 | H7: =Model!AS7 -> 0.68441509 | I7: =Model!AW7 -> 2 | J7: =Model!AX7 -> Pass | K7: =Model!I7 -> 111227.57 | L7: =Model!AZ7 -> 20283.867
A8: =Model!A8 -> 4 | B8: =Model!B8 -> First Overnight | C8: =Model!U8 -> 453714.4 | D8: =Model!AL8 -> 521613.64 | E8: =Model!AM8 -> 65321.11 | F8: =Model!AN8 -> 0.14396966 | G8: =Model!AR8 -> 0.7035888 | H8: =Model!AS8 -> 0.73649771 | I8: =Model!AW8 -> 3 | J8: =Model!AX8 -> Pass | K8: =Model!I8 -> 433466.13 | L8: =Model!AZ8 -> 59597.009
A9: =Model!A9 -> 5 | B9: =Model!B9 -> Themed Weekend | C9: =Model!U9 -> 453714.4 | D9: =Model!AL9 -> 528428.32 | E9: =Model!AM9 -> 72135.789 | F9: =Model!AN9 -> 0.15898942 | G9: =Model!AR9 -> 0.71375784 | H9: =Model!AS9 -> 0.74363705 | I9: =Model!AW9 -> 3 | J9: =Model!AX9 -> Pass | K9: =Model!I9 -> 394152.99 | L9: =Model!AZ9 -> 108083.62
A10: =Model!A10 -> 6 | B10: =Model!B10 -> Growing Up | C10: =Model!U10 -> 1539879.2 | D10: =Model!AL10 -> 1811804.2 | E10: =Model!AM10 -> 263175.01 | F10: =Model!AN10 -> 0.17090627 | G10: =Model!AR10 -> 0.72306561 | H10: =Model!AS10 -> 0.75054102 | I10: =Model!AW10 -> 3 | J10: =Model!AX10 -> Pass | K10: =Model!I10 -> 1431916.4 | L10: =Model!AZ10 -> 285343.65
A11: =Model!A11 -> 7 | B11: =Model!B11 -> The Big Booking | C11: =Model!U11 -> 2804779.9 | D11: =Model!AL11 -> 3327154.7 | E11: =Model!AM11 -> 506437.23 | F11: =Model!AN11 -> 0.1805622 | G11: =Model!AR11 -> 0.73174582 | H11: =Model!AS11 -> 0.75727348 | I11: =Model!AW11 -> 3 | J11: =Model!AX11 -> Pass | K11: =Model!I11 -> 2519656.4 | L11: =Model!AZ11 -> 640601.5
A12: =Model!A12 -> 8 | B12: =Model!B12 -> Logistics | C12: =Model!U12 -> 5499568.5 | D12: =Model!AL12 -> 6567876 | E12: =Model!AM12 -> 1037057.5 | F12: =Model!AN12 -> 0.18857071 | G12: =Model!AR12 -> 0.73996874 | H12: =Model!AS12 -> 0.76388097 | I12: =Model!AW12 -> 3 | J12: =Model!AX12 -> Pass | K12: =Model!I12 -> 4859398.5 | L12: =Model!AZ12 -> 1386095.1
A13: =Model!A13 -> 9 | B13: =Model!B13 -> The Council | C13: =Model!U13 -> 7259430.4 | D13: =Model!AL13 -> 8712134.5 | E13: =Model!AM13 -> 1411454 | F13: =Model!AN13 -> 0.19443041 | G13: =Model!AR13 -> 0.74607966 | H13: =Model!AS13 -> 0.77039741 | I13: =Model!AW13 -> 2 | J13: =Model!AX13 -> Pass | K13: =Model!I13 -> 5873904.9 | L13: =Model!AZ13 -> 2092680.5
A14: =Model!A14 -> 10 | B14: =Model!B14 -> Flagship | C14: =Model!U14 -> 17873598 | D14: =Model!AL14 -> 21537689 | E14: =Model!AM14 -> 3562529.2 | F14: =Model!AN14 -> 0.19931797 | G14: =Model!AR14 -> 0.75201617 | H14: =Model!AS14 -> 0.77683656 | I14: =Model!AW14 -> 1 | J14: =Model!AX14 -> Replay | K14: =Model!I14 -> 15782319 | L14: =Model!AZ14 -> 3761331.4
A16: Festivals passed (2 or more stars) | E16: =COUNTIF(J5:J14,"Pass") -> 9
A17: Average stars per festival | E17: =AVERAGE(I5:I14) -> 2.4
A19: How to use: change the player type, targets or cost assumptions on the Inputs sheet and watch this table. The Notes sheet lists what is invented.

Sheet Inputs
A1: Festival Manager: live economy model (expected values, no randomness)
A2: Blue cells on a yellow background are inputs you can change. Everything on the Model sheet is a formula. Choose a player type in B5.
A4: Global settings
A5: Player type | B5: Average | C5: Careless, Average or Skilled (see player types below)
A6: Starting cash (£) | B6: 20000 | C6: Cash at the start of festival 1
A7: Multi-day price uplift per extra day | B7: 0.5 | C7: Ticket price for a 2-day festival = fair price x (1 + 0.5)
A8: Food, drink and merch spend per head (share of ticket price) | B8: 0.45 | C8: Invented
A9: Merch share of ticket price per head | B9: 0.17 | C9: Used for the merch discount lever
A10: Lineup cost coefficient (x full-scale ticket revenue) | B10: 0.85 | C10: Cost of a full-quality lineup
A11: Facilities cost coefficient (x full-scale ticket revenue) | B11: 0.3 | C11: Cost of full facilities
A12: Fixed overhead (x full-scale ticket revenue) | B12: 0.37 | C12: Staff, upkeep and ground hire. 0.37 for the MVP (no sponsors, no rewarded ads)
A13: Promoter advance on? | B13: Yes | C13: Yes or No
A14: Advance tops budget up to (x full-scale ticket revenue) | B14: 1.1 | C14: Proposed rule
A15: Advance fee | B15: 0.12 | C15: Share of the advance repaid as a fee
A16: Advance fee when the festival earns 3 stars | B16: 0.06 | C16: Star-linked fee
A17: Profit measured against | B17: Planned spend | C17: Planned spend or Cash budget
A18: Rewarded ad cap (uses per festival) | B18: 0 | C18: 0 for the MVP (ads come after it); the agreed cap is 1
A19: Rewarded ad boost (share of revenue per use) | B19: 0.02 | C19: Proposed at about 2%
A20: Sponsor counts last-minute ticket sales? | B20: No | C20: Proposed: No (closes the exploit)
A21: Starting festival reputation (0 to 1) | B21: 0.5
A22: Reputation carry-over (0 to 1) | B22: 0.7 | C22: Next reputation = carry x old + (1 - carry) x average satisfaction
A23: Sponsorship on? | B23: No | C23: Parked until after the MVP, so the default is No. Set to Yes (and overhead to 0.50) for the fuller design
A24: Sponsorship tiers | B24: Payout (x full-scale ticket revenue) | C24: Attendance needed (share of capacity)
A25: Low | B25: 0.06 | C25: 0.4
A26: Middle | B26: 0.14 | C26: 0.65
A27: High | B27: 0.24 | C27: 0.85
A29: Player types
A30: Type | B30: Lineup quality (0 to 1) | C30: Facilities investment (0 to 1) | D30: Ticket price vs fair (1 = fair) | E30: Negotiation skill (0 to 1) | F30: Fee generosity (1 = fair) | G30: Event handling (0 to 1) | H30: Last-minute tickets (0 none, 1 sometimes, 2 smart) | I30: Merch discount used (0 or 1) | J30: Sponsor choice (0 greedy, 1 middle, 2 smart) | K30: Rewarded ads used (0 or 1) | L30: HQ upgrade bonus per festival
A31: Careless | B31: 0.62 | C31: 0.6 | D31: 1.08 | E31: 0.1 | F31: 0.92 | G31: 0.3 | H31: 0 | I31: 0 | J31: 0 | K31: 0 | L31: 0
A32: Average | B32: 0.75 | C32: 0.75 | D32: 1 | E32: 0.4 | F32: 1 | G32: 0.5 | H32: 1 | I32: 0 | J32: 1 | K32: 1 | L32: 0.006
A33: Skilled | B33: 0.85 | C33: 0.85 | D33: 1 | E33: 0.9 | F33: 1 | G33: 0.9 | H33: 2 | I33: 1 | J33: 2 | K33: 1 | L33: 0.01
A35: Festival ladder and targets
A36: # | B36: Festival | C36: Capacity | D36: Days | E36: Fair ticket price (£) | F36: Customer satisfaction target | G36: Band satisfaction target | H36: Profit target (% of spend)
A37: 1 | B37: Village Green | C37: 500 | D37: 1 | E37: 25 | F37: 0.6 | G37: 0.6 | H37: 0.05
A38: 2 | B38: The Local Field | C38: 1500 | D38: 1 | E38: 30 | F38: 0.6 | G38: 0.6 | H38: 0.1
A39: 3 | B39: Two Stages | C39: 3000 | D39: 1 | E39: 40 | F39: 0.62 | G39: 0.62 | H39: 0.12
A40: 4 | B40: First Overnight | C40: 5000 | D40: 2 | E40: 55 | F40: 0.64 | G40: 0.64 | H40: 0.12
A41: 5 | B41: Themed Weekend | C41: 5000 | D41: 2 | E41: 55 | F41: 0.64 | G41: 0.64 | H41: 0.12
A42: 6 | B42: Growing Up | C42: 10000 | D42: 3 | E42: 70 | F42: 0.69 | G42: 0.69 | H42: 0.16
A43: 7 | B43: The Big Booking | C43: 15000 | D43: 3 | E43: 85 | F43: 0.71 | G43: 0.71 | H43: 0.16
...

Sheet Model
A1: Model: one row per festival, for the player type chosen on Inputs
A2: Expected values with no randomness. A festival that earns fewer than 2 stars is marked Replay, but the cash and reputation still carry on as if it was passed (replays are not modelled here).
A3: Festival | H3: Funding | K3: Plan | V3: Attendance | AD3: Income | AM3: Result | AO3: Satisfaction
A4: # | B4: Festival | C4: Capacity | D4: Days | E4: Fair ticket price (£) | F4: Ticket price for the festival (£) | G4: Full-scale ticket revenue (£) | H4: Cash at start (£) | I4: Promoter advance (£) | J4: Budget (£) | K4: Planned lineup quality | L4: Planned facilities investment | M4: Planned lineup cost (£) | N4: Planned facilities cost (£) | O4: Fixed overhead (£) | P4: Squeeze factor (1 = budget covers the plan) | Q4: Lineup quality used | R4: Facilities investment used | S4: Lineup cost (£) | T4: Facilities cost (£) | U4: Total spend (£) | V4: Reputation at start | W4: Price effect (price against perceived value) | X4: Attendance potential | Y4: Attendance (share of capacity) | Z4: Facility capacity (share of capacity) | AA4: Last-minute tickets used (0 to 1) | AB4: Extra last-minute buyers (share of capacity) | AC4: Attendance including last-minute | AD4: Ticket income (£) | AE4: Food, drink and merch income (£) | AF4: Last-minute ticket income, net (£) | AG4: Merch discount income (£) | AH4: Rewarded ad uplift (£) | AI4: Sponsor tier chosen (1 low, 2 middle, 3 high) | AJ4: Sponsor attendance needed | AK4: Sponsor payment (£) | AL4: Total income (£) | AM4: Profit (£) | AN4: Profit (% of base) | AO4: Queue ratio (1 = no queues) | AP4: Fair-price factor | AQ4: Event penalty | AR4: Customer satisfaction | AS4: Band satisfaction | AT4: Profit star | AU4: Customer star | AV4: Band star | AW4: Stars | AX4: Result | AY4: Advance fee repaid (£) | AZ4: Cash at end (£) | BA4: Reputation after | BB4: Noise complaint fine (£) | BC4: Scripted event costs (£)
A5: =Inputs!A37 -> 1 | B5: =Inputs!B37 -> Village Green | C5: =Inputs!C37 -> 500 | D5: =Inputs!D37 -> 1 | E5: =Inputs!E37 -> 25 | F5: =E5*(1+Inputs!$B$7*(D5-1)) -> 25 | G5: =C5*F5 -> 12500 | H5: =Inputs!$B$6 -> 20000 | I5: =IF(Inputs!$B$13="Yes",MAX(0,Inputs!$B$14*G5-H5),0) -> 0 | J5: =H5+I5 -> 20000 | K5: =Inputs!$B$49 -> 0.75 | L5: =Inputs!$B$50 -> 0.75 | M5: =Inputs!$B$10*G5*K5^1.5*Inputs!$B$53*(1-0.1*Inputs!$B$52) -> 6625.0943 | N5: =Inputs!$B$11*G5*L5 -> 2812.5 | O5: =Inputs!$B$12*G5 -> 4625 | P5: =IF(M5+N5+O5>J5,MAX(0.15,MIN(1,(J5-O5)/(M5+N5))),1) -> 1 | Q5: =K5*P5^0.67 -> 0.75 | R5: =L5*P5 -> 0.75 | S5: =Inputs!$B$10*G5*Q5^1.5*Inputs!$B$53*(1-0.1*Inputs!$B$52) -> 6625.0943 | T5: =Inputs!$B$11*G5*R5 -> 2812.5 | U5: =S5+T5+O5 -> 14062.594 | V5: =Inputs!$B$21 -> 0.5 | W5: =MAX(0.3,1-1.1*(Inputs!$B$51/(0.6+0.6*Q5)-1)) -> 1.052381 | X5: =(0.2+0.8*Q5)*(0.75+0.5*V5)*W5 -> 0.84190476 | Y5: =MAX(0,MIN(1,X5)) -> 0.84190476 | Z5: =R5*1.25 -> 0.9375 | AA5: =IF(Inputs!$B$55=0,0,IF(Inputs!$B$55=1,IF(Y5<0.8,0.5,0),IF(AND(Y5<0.85,Z5/(Y5+0.5*(1-Y5))>=0.95),1,0))) -> 0 | AB5: =0.5*(1-Y5) -> 0.079047619 | AC5: =Y5+AA5*AB5 -> 0.84190476 | AD5: =Y5*C5*F5*Inputs!$B$51 -> 10523.81 | AE5: =Y5*C5*Inputs!$B$8*F5*MIN(1,Z5/MAX(Y5,0.0001))^0.5+AA5*AB5*C5*Inputs!$B$8*F5*MIN(1,Z5/MAX(AC5,0.0001))^0.5 -> 4735.7143 | AF5: =AA5*(AB5*C5*F5*Inputs!$B$51*0.6-0.1*Y5*C5*F5*Inputs!$B$51*0.4) -> 0 | AG5: =Inputs!$B$56*0.175*Y5*C5*(Inputs!$B$9*F5)*0.5*0.7 -> 0 | AH5: =(AD5+AE5+AF5+AG5)*Inputs!$B$19*MIN(Inputs!$B$58,Inputs!$B$18) -> 0 | AI5: =IF(Inputs!$B$57=0,3,IF(Inputs!$B$57=1,IF(MAX(0,MIN(1,X5))>=Inputs!$C$26,2,1),IF(MAX(0,MIN(1,X5))-0.07>=Inputs!$C$27,3,IF(MAX(0,MIN(1,X5))-0.07>=Inputs!$C$26,2,1)))) -> 2 | AJ5: =INDEX(Inputs!$C$25:$C$27,AI5) -> 0.65 | AK5: =IF(Inputs!$B$23="No",0,IF(IF(Inputs!$B$20="Yes",AC5,Y5)>=AJ5,INDEX(Inputs!$B$25:$B$27,AI5)*G5,0)) -> 0 | AL5: =AD5+AE5+AF5+AG5+AH5+AK5 -> 15259.524 | AM5: =AL5-U5-BB5-BC5 -> 528.17947 | AN5: =AM5/IF(Inputs!$B$17="Planned spend",U5,J5) -> 0.037559177 | AO5: =MIN(1,Z5/MAX(AC5,0.01)) -> 1 | AP5: =MAX(0,MIN(1,1-2*MAX(0,Inputs!$B$51/(0.6+0.6*Q5)-1))) -> 1 | AQ5: =0.09*(1-0.7*Inputs!$B$54) -> 0.0585 | AR5: =MAX(0,MIN(1,0.35*AO5+0.3*Q5+0.08*AP5+0.15*V5-AQ5+Inputs!$B$59*(A5-1)-IF(Inputs!$B$66="Turn down",Inputs!$B$68*IF(Inputs!$B$67="Expected",IF(A5=1,1,Inputs!$B$70),1),0)+SUMPRODUCT(('Scripted events'!$B$5:$B$60=A5)*'Scripted events'!$K$5:$K$60*'Scripted events'!$F$5:$F$60))) -> 0.6715 | AS5: =MAX(0,MIN(1,0.25+0.4*MAX(0,MIN(1,(Inputs!$B$53-0.8)/0.4))+0.2*MAX(0,MIN(1,R5/0.8))+0.1*AC5+Inputs!$B$59*(A5-1)-IF(Inputs!$B$66="Turn down",Inputs!$B$69*IF(Inputs!$B$67="Expected",IF(A5=1,1,Inputs!$B$70),1),0)+SUMPRODUCT(('Scripted events'!$B$5:$B$60=A5)*'Scripted events'!$K$5:$K$60*'Scripted events'!$G$5:$G$60))) -> 0.72169048 | AT5: =IF(AN5>=Inputs!H37,1,0) -> 0 | AU5: =IF(AR5>=Inputs!F37,1,0) -> 1 | AV5: =IF(AS5>=Inputs!G37,1,0) -> 1 | AW5: =AT5+AU5+AV5 -> 2 | AX5: =IF(AW5>=2,"Pass","Replay") -> Pass | AY5: =IF(AW5=3,Inputs!$B$16,Inputs!$B$15)*I5 -> 0 | AZ5: =MAX(0,J5+AM5-I5-AY5) -> 20528.179 | BA5: =Inputs!$B$22*V5+(1-Inputs!$B$22)*(AR5+AS5)/2+SUMPRODUCT(('Scripted events'!$B$5:$B$60=A5)*'Scripted events'!$K$5:$K$60*'Scripted events'!$H$5:$H$60) -> 0.55897857 | BB5: =IF(Inputs!$B$66="Ignore",IF(Inputs!$B$67="Fined",1,IF(Inputs!$B$67="Not fined",0,Inputs!$B$65*IF(A5=1,1,Inputs!$B$70)))*IF(Inputs!$B$63="Yes",Inputs!$B$64*G5,Inputs!$B$62),0) -> 156.25 | BC5: =SUMPRODUCT(('Scripted events'!$B$5:$B$60=A5)*'Scripted events'!$K$5:$K$60*'Scripted events'!$E$5:$E$60)*G5 -> 512.5
A6: =Inputs!A38 -> 2 | B6: =Inputs!B38 -> The Local Field | C6: =Inputs!C38 -> 1500 | D6: =Inputs!D38 -> 1 | E6: =Inputs!E38 -> 30 | F6: =E6*(1+Inputs!$B$7*(D6-1)) -> 30 | G6: =C6*F6 -> 45000 | H6: =AZ5 -> 20528.179 | I6: =IF(Inputs!$B$13="Yes",MAX(0,Inputs!$B$14*G6-H6),0) -> 28971.821 | J6: =H6+I6 -> 49500 | K6: =Inputs!$B$49 -> 0.75 | L6: =Inputs!$B$50 -> 0.75 | M6: =Inputs!$B$10*G6*K6^1.5*Inputs!$B$53*(1-0.1*Inputs!$B$52) -> 23850.34 | N6: =Inputs!$B$11*G6*L6 -> 10125 | O6: =Inputs!$B$12*G6 -> 16650 | P6: =IF(M6+N6+O6>J6,MAX(0.15,MIN(1,(J6-O6)/(M6+N6))),1) -> 0.96687775 | Q6: =K6*P6^0.67 -> 0.73326375 | R6: =L6*P6 -> 0.72515831 | S6: =Inputs!$B$10*G6*Q6^1.5*Inputs!$B$53*(1-0.1*Inputs!$B$52) -> 23056.479 | T6: =Inputs!$B$11*G6*R6 -> 9789.6372 | U6: =S6+T6+O6 -> 49496.117 | V6: =BA5 -> 0.55897857 | W6: =MAX(0.3,1-1.1*(Inputs!$B$51/(0.6+0.6*Q6)-1)) -> 1.0422652 | X6: =(0.2+0.8*Q6)*(0.75+0.5*V6)*W6 -> 0.8440343 | Y6: =MAX(0,MIN(1,X6)) -> 0.8440343 | Z6: =R6*1.25 -> 0.90644789 | AA6: =IF(Inputs!$B$55=0,0,IF(Inputs!$B$55=1,IF(Y6<0.8,0.5,0),IF(AND(Y6<0.85,Z6/(Y6+0.5*(1-Y6))>=0.95),1,0))) -> 0 | AB6: =0.5*(1-Y6) -> 0.077982852 | AC6: =Y6+AA6*AB6 -> 0.8440343 | AD6: =Y6*C6*F6*Inputs!$B$51 -> 37981.543 | AE6: =Y6*C6*Inputs!$B$8*F6*MIN(1,Z6/MAX(Y6,0.0001))^0.5+AA6*AB6*C6*Inputs!$B$8*F6*MIN(1,Z6/MAX(AC6,0.0001))^0.5 -> 17091.695 | AF6: =AA6*(AB6*C6*F6*Inputs!$B$51*0.6-0.1*Y6*C6*F6*Inputs!$B$51*0.4) -> 0 | AG6: =Inputs!$B$56*0.175*Y6*C6*(Inputs!$B$9*F6)*0.5*0.7 -> 0 | AH6: =(AD6+AE6+AF6+AG6)*Inputs!$B$19*MIN(Inputs!$B$58,Inputs!$B$18) -> 0 | AI6: =IF(Inputs!$B$57=0,3,IF(Inputs!$B$57=1,IF(MAX(0,MIN(1,X6))>=Inputs!$C$26,2,1),IF(MAX(0,MIN(1,X6))-0.07>=Inputs!$C$27,3,IF(MAX(0,MIN(1,X6))-0.07>=Inputs!$C$26,2,1)))) -> 2 | AJ6: =INDEX(Inputs!$C$25:$C$27,AI6) -> 0.65 | AK6: =IF(Inputs!$B$23="No",0,IF(IF(Inputs!$B$20="Yes",AC6,Y6)>=AJ6,INDEX(Inputs!$B$25:$B$27,AI6)*G6,0)) -> 0 | AL6: =AD6+AE6+AF6+AG6+AH6+AK6 -> 55073.238 | AM6: =AL6-U6-BB6-BC6 -> 3720.8712 | AN6: =AM6/IF(Inputs!$B$17="Planned spend",U6,J6) -> 0.075175014 | AO6: =MIN(1,Z6/MAX(AC6,0.01)) -> 1 | AP6: =MAX(0,MIN(1,1-2*MAX(0,Inputs!$B$51/(0.6+0.6*Q6)-1))) -> 1 | AQ6: =0.09*(1-0.7*Inputs!$B$54) -> 0.0585 | AR6: =MAX(0,MIN(1,0.35*AO6+0.3*Q6+0.08*AP6+0.15*V6-AQ6+Inputs!$B$59*(A6-1)-IF(Inputs!$B$66="Turn down",Inputs!$B$68*IF(Inputs!$B$67="Expected",IF(A6=1,1,Inputs!$B$70),1),0)+SUMPRODUCT(('Scripted events'!$B$5:$B$60=A6)*'Scripted events'!$K$5:$K$60*'Scripted events'!$F$5:$F$60))) -> 0.67632591 | AS6: =MAX(0,MIN(1,0.25+0.4*MAX(0,MIN(1,(Inputs!$B$53-0.8)/0.4))+0.2*MAX(0,MIN(1,R6/0.8))+0.1*AC6+Inputs!$B$59*(A6-1)-IF(Inputs!$B$66="Turn down",Inputs!$B$69*IF(Inputs!$B$67="Expected",IF(A6=1,1,Inputs!$B$70),1),0)+SUMPRODUCT(('Scripted events'!$B$5:$B$60=A6)*'Scripted events'!$K$5:$K$60*'Scripted events'!$G$5:$G$60))) -> 0.72169301 | AT6: =IF(AN6>=Inputs!H38,1,0) -> 0 | AU6: =IF(AR6>=Inputs!F38,1,0) -> 1 | AV6: =IF(AS6>=Inputs!G38,1,0) -> 1 | AW6: =AT6+AU6+AV6 -> 2 | AX6: =IF(AW6>=2,"Pass","Replay") -> Pass | AY6: =IF(AW6=3,Inputs!$B$16,Inputs!$B$15)*I6 -> 3476.6185 | AZ6: =MAX(0,J6+AM6-I6-AY6) -> 20772.432 | BA6: =Inputs!$B$22*V6+(1-Inputs!$B$22)*(AR6+AS6)/2+SUMPRODUCT(('Scripted events'!$B$5:$B$60=A6)*'Scripted events'!$K$5:$K$60*'Scripted events'!$H$5:$H$60) -> 0.60098784 | BB6: =IF(Inputs!$B$66="Ignore",IF(Inputs!$B$67="Fined",1,IF(Inputs!$B$67="Not fined",0,Inputs!$B$65*IF(A6=1,1,Inputs!$B$70)))*IF(Inputs!$B$63="Yes",Inputs!$B$64*G6,Inputs!$B$62),0) -> 281.25 | BC6: =SUMPRODUCT(('Scripted events'!$B$5:$B$60=A6)*'Scripted events'!$K$5:$K$60*'Scripted events'!$E$5:$E$60)*G6 -> 1575
A7: =Inputs!A39 -> 3 | B7: =Inputs!B39 -> Two Stages | C7: =Inputs!C39 -> 3000 | D7: =Inputs!D39 -> 1 | E7: =Inputs!E39 -> 40 | F7: =E7*(1+Inputs!$B$7*(D7-1)) -> 40 | G7: =C7*F7 -> 120000 | H7: =AZ6 -> 20772.432 | I7: =IF(Inputs!$B$13="Yes",MAX(0,Inputs!$B$14*G7-H7),0) -> 111227.57 | J7: =H7+I7 -> 132000 | K7: =Inputs!$B$49 -> 0.75 | L7: =Inputs!$B$50 -> 0.75 | M7: =Inputs!$B$10*G7*K7^1.5*Inputs!$B$53*(1-0.1*Inputs!$B$52) -> 63600.906 | N7: =Inputs!$B$11*G7*L7 -> 27000 | O7: =Inputs!$B$12*G7 -> 44400 | P7: =IF(M7+N7+O7>J7,MAX(0.15,MIN(1,(J7-O7)/(M7+N7))),1) -> 0.96687775 | Q7: =K7*P7^0.67 -> 0.73326375 | R7: =L7*P7 -> 0.72515831 | S7: =Inputs!$B$10*G7*Q7^1.5*Inputs!$B$53*(1-0.1*Inputs!$B$52) -> 61483.945 | T7: =Inputs!$B$11*G7*R7 -> 26105.699 | U7: =S7+T7+O7 -> 131989.64 | V7: =BA6 -> 0.60098784 | W7: =MAX(0.3,1-1.1*(Inputs!$B$51/(0.6+0.6*Q7)-1)) -> 1.0422652 | X7: =(0.2+0.8*Q7)*(0.75+0.5*V7)*W7 -> 0.8612551 | Y7: =MAX(0,MIN(1,X7)) -> 0.8612551 | Z7: =R7*1.25 -> 0.90644789 | AA7: =IF(Inputs!$B$55=0,0,IF(Inputs!$B$55=1,IF(Y7<0.8,0.5,0),IF(AND(Y7<0.85,Z7/(Y7+0.5*(1-Y7))>=0.95),1,0))) -> 0 | AB7: =0.5*(1-Y7) -> 0.069372451 | AC7: =Y7+AA7*AB7 -> 0.8612551 | AD7: =Y7*C7*F7*Inputs!$B$51 -> 103350.61 | AE7: =Y7*C7*Inputs!$B$8*F7*MIN(1,Z7/MAX(Y7,0.0001))^0.5+AA7*AB7*C7*Inputs!$B$8*F7*MIN(1,Z7/MAX(AC7,0.0001))^0.5 -> 46507.775 | AF7: =AA7*(AB7*C7*F7*Inputs!$B$51*0.6-0.1*Y7*C7*F7*Inputs!$B$51*0.4) -> 0 | AG7: =Inputs!$B$56*0.175*Y7*C7*(Inputs!$B$9*F7)*0.5*0.7 -> 0 | AH7: =(AD7+AE7+AF7+AG7)*Inputs!$B$19*MIN(Inputs!$B$58,Inputs!$B$18) -> 0 | AI7: =IF(Inputs!$B$57=0,3,IF(Inputs!$B$57=1,IF(MAX(0,MIN(1,X7))>=Inputs!$C$26,2,1),IF(MAX(0,MIN(1,X7))-0.07>=Inputs!$C$27,3,IF(MAX(0,MIN(1,X7))-0.07>=Inputs!$C$26,2,1)))) -> 2 | AJ7: =INDEX(Inputs!$C$25:$C$27,AI7) -> 0.65 | AK7: =IF(Inputs!$B$23="No",0,IF(IF(Inputs!$B$20="Yes",AC7,Y7)>=AJ7,INDEX(Inputs!$B$25:$B$27,AI7)*G7,0)) -> 0 | AL7: =AD7+AE7+AF7+AG7+AH7+AK7 -> 149858.39 | AM7: =AL7-U7-BB7-BC7 -> 12858.743 | AN7: =AM7/IF(Inputs!$B$17="Planned spend",U7,J7) -> 0.097422361 | AO7: =MIN(1,Z7/MAX(AC7,0.01)) -> 1 | AP7: =MAX(0,MIN(1,1-2*MAX(0,Inputs!$B$51/(0.6+0.6*Q7)-1))) -> 1 | AQ7: =0.09*(1-0.7*Inputs!$B$54) -> 0.0585 | AR7: =MAX(0,MIN(1,0.35*AO7+0.3*Q7+0.08*AP7+0.15*V7-AQ7+Inputs!$B$59*(A7-1)-IF(Inputs!$B$66="Turn down",Inputs!$B$68*IF(Inputs!$B$67="Expected",IF(A7=1,1,Inputs!$B$70),1),0)+SUMPRODUCT(('Scripted events'!$B$5:$B$60=A7)*'Scripted events'!$K$5:$K$60*'Scripted events'!$F$5:$F$60))) -> 0.6936273 | AS7: =MAX(0,MIN(1,0.25+0.4*MAX(0,MIN(1,(Inputs!$B$53-0.8)/0.4))+0.2*MAX(0,MIN(1,R7/0.8))+0.1*AC7+Inputs!$B$59*(A7-1)-IF(Inputs!$B$66="Turn down",Inputs!$B$69*IF(Inputs!$B$67="Expected",IF(A7=1,1,Inputs!$B$70),1),0)+SUMPRODUCT(('Scripted events'!$B$5:$B$60=A7)*'Scripted events'!$K$5:$K$60*'Scripted events'!$G$5:$G$60))) -> 0.68441509 | AT7: =IF(AN7>=Inputs!H39,1,0) -> 0 | AU7: =IF(AR7>=Inputs!F39,1,0) -> 1 | AV7: =IF(AS7>=Inputs!G39,1,0) -> 1 | AW7: =AT7+AU7+AV7 -> 2 | AX7: =IF(AW7>=2,"Pass","Replay") -> Pass | AY7: =IF(AW7=3,Inputs!$B$16,Inputs!$B$15)*I7 -> 13347.308 | AZ7: =MAX(0,J7+AM7-I7-AY7) -> 20283.867 | BA7: =Inputs!$B$22*V7+(1-Inputs!$B$22)*(AR7+AS7)/2+SUMPRODUCT(('Scripted events'!$B$5:$B$60=A7)*'Scripted events'!$K$5:$K$60*'Scripted events'!$H$5:$H$60) -> 0.62739784 | BB7: =IF(Inputs!$B$66="Ignore",IF(Inputs!$B$67="Fined",1,IF(Inputs!$B$67="Not fined",0,Inputs!$B$65*IF(A7=1,1,Inputs!$B$70)))*IF(Inputs!$B$63="Yes",Inputs!$B$64*G7,Inputs!$B$62),0) -> 750 | BC7: =SUMPRODUCT(('Scripted events'!$B$5:$B$60=A7)*'Scripted events'!$K$5:$K$60*'Scripted events'!$E$5:$E$60)*G7 -> 4260
A8: =Inputs!A40 -> 4 | B8: =Inputs!B40 -> First Overnight | C8: =Inputs!C40 -> 5000 | D8: =Inputs!D40 -> 2 | E8: =Inputs!E40 -> 55 | F8: =E8*(1+Inputs!$B$7*(D8-1)) -> 82.5 | G8: =C8*F8 -> 412500 | H8: =AZ7 -> 20283.867 | I8: =IF(Inputs!$B$13="Yes",MAX(0,Inputs!$B$14*G8-H8),0) -> 433466.13 | J8: =H8+I8 -> 453750 | K8: =Inputs!$B$49 -> 0.75 | L8: =Inputs!$B$50 -> 0.75 | M8: =Inputs!$B$10*G8*K8^1.5*Inputs!$B$53*(1-0.1*Inputs!$B$52) -> 218628.11 | N8: =Inputs!$B$11*G8*L8 -> 92812.5 | O8: =Inputs!$B$12*G8 -> 152625 | P8: =IF(M8+N8+O8>J8,MAX(0.15,MIN(1,(J8-O8)/(M8+N8))),1) -> 0.96687775 | Q8: =K8*P8^0.67 -> 0.73326375 | R8: =L8*P8 -> 0.72515831 | S8: =Inputs!$B$10*G8*Q8^1.5*Inputs!$B$53*(1-0.1*Inputs!$B$52) -> 211351.06 | T8: =Inputs!$B$11*G8*R8 -> 89738.341 | U8: =S8+T8+O8 -> 453714.4 | V8: =BA7 -> 0.62739784 | W8: =MAX(0.3,1-1.1*(Inputs!$B$51/(0.6+0.6*Q8)-1)) -> 1.0422652 | X8: =(0.2+0.8*Q8)*(0.75+0.5*V8)*W8 -> 0.87208132 | Y8: =MAX(0,MIN(1,X8)) -> 0.87208132 | Z8: =R8*1.25 -> 0.90644789 | AA8: =IF(Inputs!$B$55=0,0,IF(Inputs!$B$55=1,IF(Y8<0.8,0.5,0),IF(AND(Y8<0.85,Z8/(Y8+0.5*(1-Y8))>=0.95),1,0))) -> 0 | AB8: =0.5*(1-Y8) -> 0.063959342 | AC8: =Y8+AA8*AB8 -> 0.87208132 | AD8: =Y8*C8*F8*Inputs!$B$51 -> 359733.54 | AE8: =Y8*C8*Inputs!$B$8*F8*MIN(1,Z8/MAX(Y8,0.0001))^0.5+AA8*AB8*C8*Inputs!$B$8*F8*MIN(1,Z8/MAX(AC8,0.0001))^0.5 -> 161880.09 | AF8: =AA8*(AB8*C8*F8*Inputs!$B$51*0.6-0.1*Y8*C8*F8*Inputs!$B$51*0.4) -> 0 | AG8: =Inputs!$B$56*0.175*Y8*C8*(Inputs!$B$9*F8)*0.5*0.7 -> 0 | AH8: =(AD8+AE8+AF8+AG8)*Inputs!$B$19*MIN(Inputs!$B$58,Inputs!$B$18) -> 0 | AI8: =IF(Inputs!$B$57=0,3,IF(Inputs!$B$57=1,IF(MAX(0,MIN(1,X8))>=Inputs!$C$26,2,1),IF(MAX(0,MIN(1,X8))-0.07>=Inputs!$C$27,3,IF(MAX(0,MIN(1,X8))-0.07>=Inputs!$C$26,2,1)))) -> 2 | AJ8: =INDEX(Inputs!$C$25:$C$27,AI8) -> 0.65 | AK8: =IF(Inputs!$B$23="No",0,IF(IF(Inputs!$B$20="Yes",AC8,Y8)>=AJ8,INDEX(Inputs!$B$25:$B$27,AI8)*G8,0)) -> 0 | AL8: =AD8+AE8+AF8+AG8+AH8+AK8 -> 521613.64 | AM8: =AL8-U8-BB8-BC8 -> 65321.11 | AN8: =AM8/IF(Inputs!$B$17="Planned spend",U8,J8) -> 0.14396966 | AO8: =MIN(1,Z8/MAX(AC8,0.01)) -> 1 | AP8: =MAX(0,MIN(1,1-2*MAX(0,Inputs!$B$51/(0.6+0.6*Q8)-1))) -> 1 | AQ8: =0.09*(1-0.7*Inputs!$B$54) -> 0.0585 | AR8: =MAX(0,MIN(1,0.35*AO8+0.3*Q8+0.08*AP8+0.15*V8-AQ8+Inputs!$B$59*(A8-1)-IF(Inputs!$B$66="Turn down",Inputs!$B$68*IF(Inputs!$B$67="Expected",IF(A8=1,1,Inputs!$B$70),1),0)+SUMPRODUCT(('Scripted events'!$B$5:$B$60=A8)*'Scripted events'!$K$5:$K$60*'Scripted events'!$F$5:$F$60))) -> 0.7035888 | AS8: =MAX(0,MIN(1,0.25+0.4*MAX(0,MIN(1,(Inputs!$B$53-0.8)/0.4))+0.2*MAX(0,MIN(1,R8/0.8))+0.1*AC8+Inputs!$B$59*(A8-1)-IF(Inputs!$B$66="Turn down",Inputs!$B$69*IF(Inputs!$B$67="Expected",IF(A8=1,1,Inputs!$B$70),1),0)+SUMPRODUCT(('Scripted events'!$B$5:$B$60=A8)*'Scripted events'!$K$5:$K$60*'Scripted events'!$G$5:$G$60))) -> 0.73649771 | AT8: =IF(AN8>=Inputs!H40,1,0) -> 1 | AU8: =IF(AR8>=Inputs!F40,1,0) -> 1 | AV8: =IF(AS8>=Inputs!G40,1,0) -> 1 | AW8: =AT8+AU8+AV8 -> 3 | AX8: =IF(AW8>=2,"Pass","Replay") -> Pass | AY8: =IF(AW8=3,Inputs!$B$16,Inputs!$B$15)*I8 -> 26007.968 | AZ8: =MAX(0,J8+AM8-I8-AY8) -> 59597.009 | BA8: =Inputs!$B$22*V8+(1-Inputs!$B$22)*(AR8+AS8)/2+SUMPRODUCT(('Scripted events'!$B$5:$B$60=A8)*'Scripted events'!$K$5:$K$60*'Scripted events'!$H$5:$H$60) -> 0.65519147 | BB8: =IF(Inputs!$B$66="Ignore",IF(Inputs!$B$67="Fined",1,IF(Inputs!$B$67="Not fined",0,Inputs!$B$65*IF(A8=1,1,Inputs!$B$70)))*IF(Inputs!$B$63="Yes",Inputs!$B$64*G8,Inputs!$B$62),0) -> 2578.125 | BC8: =SUMPRODUCT(('Scripted events'!$B$5:$B$60=A8)*'Scripted events'!$K$5:$K$60*'Scripted events'!$E$5:$E$60)*G8 -> 0
A9: =Inputs!A41 -> 5 | B9: =Inputs!B41 -> Themed Weekend | C9: =Inputs!C41 -> 5000 | D9: =Inputs!D41 -> 2 | E9: =Inputs!E41 -> 55 | F9: =E9*(1+Inputs!$B$7*(D9-1)) -> 82.5 | G9: =C9*F9 -> 412500 | H9: =AZ8 -> 59597.009 | I9: =IF(Inputs!$B$13="Yes",MAX(0,Inputs!$B$14*G9-H9),0) -> 394152.99 | J9: =H9+I9 -> 453750 | K9: =Inputs!$B$49 -> 0.75 | L9: =Inputs!$B$50 -> 0.75 | M9: =Inputs!$B$10*G9*K9^1.5*Inputs!$B$53*(1-0.1*Inputs!$B$52) -> 218628.11 | N9: =Inputs!$B$11*G9*L9 -> 92812.5 | O9: =Inputs!$B$12*G9 -> 152625 | P9: =IF(M9+N9+O9>J9,MAX(0.15,MIN(1,(J9-O9)/(M9+N9))),1) -> 0.96687775 | Q9: =K9*P9^0.67 -> 0.73326375 | R9: =L9*P9 -> 0.72515831 | S9: =Inputs!$B$10*G9*Q9^1.5*Inputs!$B$53*(1-0.1*Inputs!$B$52) -> 211351.06 | T9: =Inputs!$B$11*G9*R9 -> 89738.341 | U9: =S9+T9+O9 -> 453714.4 | V9: =BA8 -> 0.65519147 | W9: =MAX(0.3,1-1.1*(Inputs!$B$51/(0.6+0.6*Q9)-1)) -> 1.0422652 | X9: =(0.2+0.8*Q9)*(0.75+0.5*V9)*W9 -> 0.88347472 | Y9: =MAX(0,MIN(1,X9)) -> 0.88347472 | Z9: =R9*1.25 -> 0.90644789 | AA9: =IF(Inputs!$B$55=0,0,IF(Inputs!$B$55=1,IF(Y9<0.8,0.5,0),IF(AND(Y9<0.85,Z9/(Y9+0.5*(1-Y9))>=0.95),1,0))) -> 0 | AB9: =0.5*(1-Y9) -> 0.058262641 | AC9: =Y9+AA9*AB9 -> 0.88347472 | AD9: =Y9*C9*F9*Inputs!$B$51 -> 364433.32 | AE9: =Y9*C9*Inputs!$B$8*F9*MIN(1,Z9/MAX(Y9,0.0001))^0.5+AA9*AB9*C9*Inputs!$B$8*F9*MIN(1,Z9/MAX(AC9,0.0001))^0.5 -> 163994.99 | AF9: =AA9*(AB9*C9*F9*Inputs!$B$51*0.6-0.1*Y9*C9*F9*Inputs!$B$51*0.4) -> 0 | AG9: =Inputs!$B$56*0.175*Y9*C9*(Inputs!$B$9*F9)*0.5*0.7 -> 0 | AH9: =(AD9+AE9+AF9+AG9)*Inputs!$B$19*MIN(Inputs!$B$58,Inputs!$B$18) -> 0 | AI9: =IF(Inputs!$B$57=0,3,IF(Inputs!$B$57=1,IF(MAX(0,MIN(1,X9))>=Inputs!$C$26,2,1),IF(MAX(0,MIN(1,X9))-0.07>=Inputs!$C$27,3,IF(MAX(0,MIN(1,X9))-0.07>=Inputs!$C$26,2,1)))) -> 2 | AJ9: =INDEX(Inputs!$C$25:$C$27,AI9) -> 0.65 | AK9: =IF(Inputs!$B$23="No",0,IF(IF(Inputs!$B$20="Yes",AC9,Y9)>=AJ9,INDEX(Inputs!$B$25:$B$27,AI9)*G9,0)) -> 0 | AL9: =AD9+AE9+AF9+AG9+AH9+AK9 -> 528428.32 | AM9: =AL9-U9-BB9-BC9 -> 72135.789 | AN9: =AM9/IF(Inputs!$B$17="Planned spend",U9,J9) -> 0.15898942 | AO9: =MIN(1,Z9/MAX(AC9,0.01)) -> 1 | AP9: =MAX(0,MIN(1,1-2*MAX(0,Inputs!$B$51/(0.6+0.6*Q9)-1))) -> 1 | AQ9: =0.09*(1-0.7*Inputs!$B$54) -> 0.0585 | AR9: =MAX(0,MIN(1,0.35*AO9+0.3*Q9+0.08*AP9+0.15*V9-AQ9+Inputs!$B$59*(A9-1)-IF(Inputs!$B$66="Turn down",Inputs!$B$68*IF(Inputs!$B$67="Expected",IF(A9=1,1,Inputs!$B$70),1),0)+SUMPRODUCT(('Scripted events'!$B$5:$B$60=A9)*'Scripted events'!$K$5:$K$60*'Scripted events'!$F$5:$F$60))) -> 0.71375784 | AS9: =MAX(0,MIN(1,0.25+0.4*MAX(0,MIN(1,(Inputs!$B$53-0.8)/0.4))+0.2*MAX(0,MIN(1,R9/0.8))+0.1*AC9+Inputs!$B$59*(A9-1)-IF(Inputs!$B$66="Turn down",Inputs!$B$69*IF(Inputs!$B$67="Expected",IF(A9=1,1,Inputs!$B$70),1),0)+SUMPRODUCT(('Scripted events'!$B$5:$B$60=A9)*'Scripted events'!$K$5:$K$60*'Scripted events'!$G$5:$G$60))) -> 0.74363705 | AT9: =IF(AN9>=Inputs!H41,1,0) -> 1 | AU9: =IF(AR9>=Inputs!F41,1,0) -> 1 | AV9: =IF(AS9>=Inputs!G41,1,0) -> 1 | AW9: =AT9+AU9+AV9 -> 3 | AX9: =IF(AW9>=2,"Pass","Replay") -> Pass | AY9: =IF(AW9=3,Inputs!$B$16,Inputs!$B$15)*I9 -> 23649.179 | AZ9: =MAX(0,J9+AM9-I9-AY9) -> 108083.62 | BA9: =Inputs!$B$22*V9+(1-Inputs!$B$22)*(AR9+AS9)/2+SUMPRODUCT(('Scripted events'!$B$5:$B$60=A9)*'Scripted events'!$K$5:$K$60*'Scripted events'!$H$5:$H$60) -> 0.67724326 | BB9: =IF(Inputs!$B$66="Ignore",IF(Inputs!$B$67="Fined",1,IF(Inputs!$B$67="Not fined",0,Inputs!$B$65*IF(A9=1,1,Inputs!$B$70)))*IF(Inputs!$B$63="Yes",Inputs!$B$64*G9,Inputs!$B$62),0) -> 2578.125 | BC9: =SUMPRODUCT(('Scripted events'!$B$5:$B$60=A9)*'Scripted events'!$K$5:$K$60*'Scripted events'!$E$5:$E$60)*G9 -> 0
A10: =Inputs!A42 -> 6 | B10: =Inputs!B42 -> Growing Up | C10: =Inputs!C42 -> 10000 | D10: =Inputs!D42 -> 3 | E10: =Inputs!E42 -> 70 | F10: =E10*(1+Inputs!$B$7*(D10-1)) -> 140 | G10: =C10*F10 -> 1400000 | H10: =AZ9 -> 108083.62 | I10: =IF(Inputs!$B$13="Yes",MAX(0,Inputs!$B$14*G10-H10),0) -> 1431916.4 | J10: =H10+I10 -> 1540000 | K10: =Inputs!$B$49 -> 0.75 | L10: =Inputs!$B$50 -> 0.75 | M10: =Inputs!$B$10*G10*K10^1.5*Inputs!$B$53*(1-0.1*Inputs!$B$52) -> 742010.57 | N10: =Inputs!$B$11*G10*L10 -> 315000 | O10: =Inputs!$B$12*G10 -> 518000 | P10: =IF(M10+N10+O10>J10,MAX(0.15,MIN(1,(J10-O10)/(M10+N10))),1) -> 0.96687775 | Q10: =K10*P10^0.67 -> 0.73326375 | R10: =L10*P10 -> 0.72515831 | S10: =Inputs!$B$10*G10*Q10^1.5*Inputs!$B$53*(1-0.1*Inputs!$B$52) -> 717312.69 | T10: =Inputs!$B$11*G10*R10 -> 304566.49 | U10: =S10+T10+O10 -> 1539879.2 | V10: =BA9 -> 0.67724326 | W10: =MAX(0.3,1-1.1*(Inputs!$B$51/(0.6+0.6*Q10)-1)) -> 1.0422652 | X10: =(0.2+0.8*Q10)*(0.75+0.5*V10)*W10 -> 0.89251438 | Y10: =MAX(0,MIN(1,X10)) -> 0.89251438 | Z10: =R10*1.25 -> 0.90644789 | AA10: =IF(Inputs!$B$55=0,0,IF(Inputs!$B$55=1,IF(Y10<0.8,0.5,0),IF(AND(Y10<0.85,Z10/(Y10+0.5*(1-Y10))>=0.95),1,0))) -> 0 | AB10: =0.5*(1-Y10) -> 0.05374281 | AC10: =Y10+AA10*AB10 -> 0.89251438 | AD10: =Y10*C10*F10*Inputs!$B$51 -> 1249520.1 | AE10: =Y10*C10*Inputs!$B$8*F10*MIN(1,Z10/MAX(Y10,0.0001))^0.5+AA10*AB10*C10*Inputs!$B$8*F10*MIN(1,Z10/MAX(AC10,0.0001))^0.5 -> 562284.06 | AF10: =AA10*(AB10*C10*F10*Inputs!$B$51*0.6-0.1*Y10*C10*F10*Inputs!$B$51*0.4) -> 0 | AG10: =Inputs!$B$56*0.175*Y10*C10*(Inputs!$B$9*F10)*0.5*0.7 -> 0 | AH10: =(AD10+AE10+AF10+AG10)*Inputs!$B$19*MIN(Inputs!$B$58,Inputs!$B$18) -> 0 | AI10: =IF(Inputs!$B$57=0,3,IF(Inputs!$B$57=1,IF(MAX(0,MIN(1,X10))>=Inputs!$C$26,2,1),IF(MAX(0,MIN(1,X10))-0.07>=Inputs!$C$27,3,IF(MAX(0,MIN(1,X10))-0.07>=Inputs!$C$26,2,1)))) -> 2 | AJ10: =INDEX(Inputs!$C$25:$C$27,AI10) -> 0.65 | AK10: =IF(Inputs!$B$23="No",0,IF(IF(Inputs!$B$20="Yes",AC10,Y10)>=AJ10,INDEX(Inputs!$B$25:$B$27,AI10)*G10,0)) -> 0 | AL10: =AD10+AE10+AF10+AG10+AH10+AK10 -> 1811804.2 | AM10: =AL10-U10-BB10-BC10 -> 263175.01 | AN10: =AM10/IF(Inputs!$B$17="Planned spend",U10,J10) -> 0.17090627 | AO10: =MIN(1,Z10/MAX(AC10,0.01)) -> 1 | AP10: =MAX(0,MIN(1,1-2*MAX(0,Inputs!$B$51/(0.6+0.6*Q10)-1))) -> 1 | AQ10: =0.09*(1-0.7*Inputs!$B$54) -> 0.0585 | AR10: =MAX(0,MIN(1,0.35*AO10+0.3*Q10+0.08*AP10+0.15*V10-AQ10+Inputs!$B$59*(A10-1)-IF(Inputs!$B$66="Turn down",Inputs!$B$68*IF(Inputs!$B$67="Expected",IF(A10=1,1,Inputs!$B$70),1),0)+SUMPRODUCT(('Scripted events'!$B$5:$B$60=A10)*'Scripted events'!$K$5:$K$60*'Scripted events'!$F$5:$F$60))) -> 0.72306561 | AS10: =MAX(0,MIN(1,0.25+0.4*MAX(0,MIN(1,(Inputs!$B$53-0.8)/0.4))+0.2*MAX(0,MIN(1,R10/0.8))+0.1*AC10+Inputs!$B$59*(A10-1)-IF(Inputs!$B$66="Turn down",Inputs!$B$69*IF(Inputs!$B$67="Expected",IF(A10=1,1,Inputs!$B$70),1),0)+SUMPRODUCT(('Scripted events'!$B$5:$B$60=A10)*'Scripted events'!$K$5:$K$60*'Scripted events'!$G$5:$G$60))) -> 0.75054102 | AT10: =IF(AN10>=Inputs!H42,1,0) -> 1 | AU10: =IF(AR10>=Inputs!F42,1,0) -> 1 | AV10: =IF(AS10>=Inputs!G42,1,0) -> 1 | AW10: =AT10+AU10+AV10 -> 3 | AX10: =IF(AW10>=2,"Pass","Replay") -> Pass | AY10: =IF(AW10=3,Inputs!$B$16,Inputs!$B$15)*I10 -> 85914.983 | AZ10: =MAX(0,J10+AM10-I10-AY10) -> 285343.65 | BA10: =Inputs!$B$22*V10+(1-Inputs!$B$22)*(AR10+AS10)/2+SUMPRODUCT(('Scripted events'!$B$5:$B$60=A10)*'Scripted events'!$K$5:$K$60*'Scripted events'!$H$5:$H$60) -> 0.69511128 | BB10: =IF(Inputs!$B$66="Ignore",IF(Inputs!$B$67="Fined",1,IF(Inputs!$B$67="Not fined",0,Inputs!$B$65*IF(A10=1,1,Inputs!$B$70)))*IF(Inputs!$B$63="Yes",Inputs!$B$64*G10,Inputs!$B$62),0) -> 8750 | BC10: =SUMPRODUCT(('Scripted events'!$B$5:$B$60=A10)*'Scripted events'!$K$5:$K$60*'Scripted events'!$E$5:$E$60)*G10 -> 0
A11: =Inputs!A43 -> 7 | B11: =Inputs!B43 -> The Big Booking | C11: =Inputs!C43 -> 15000 | D11: =Inputs!D43 -> 3 | E11: =Inputs!E43 -> 85 | F11: =E11*(1+Inputs!$B$7*(D11-1)) -> 170 | G11: =C11*F11 -> 2550000 | H11: =AZ10 -> 285343.65 | I11: =IF(Inputs!$B$13="Yes",MAX(0,Inputs!$B$14*G11-H11),0) -> 2519656.4 | J11: =H11+I11 -> 2805000 | K11: =Inputs!$B$49 -> 0.75 | L11: =Inputs!$B$50 -> 0.75 | M11: =Inputs!$B$10*G11*K11^1.5*Inputs!$B$53*(1-0.1*Inputs!$B$52) -> 1351519.2 | N11: =Inputs!$B$11*G11*L11 -> 573750 | O11: =Inputs!$B$12*G11 -> 943500 | P11: =IF(M11+N11+O11>J11,MAX(0.15,MIN(1,(J11-O11)/(M11+N11))),1) -> 0.96687775 | Q11: =K11*P11^0.67 -> 0.73326375 | R11: =L11*P11 -> 0.72515831 | S11: =Inputs!$B$10*G11*Q11^1.5*Inputs!$B$53*(1-0.1*Inputs!$B$52) -> 1306533.8 | T11: =Inputs!$B$11*G11*R11 -> 554746.11 | U11: =S11+T11+O11 -> 2804779.9 | V11: =BA10 -> 0.69511128 | W11: =MAX(0.3,1-1.1*(Inputs!$B$51/(0.6+0.6*Q11)-1)) -> 1.0422652 | X11: =(0.2+0.8*Q11)*(0.75+0.5*V11)*W11 -> 0.89983899 | Y11: =MAX(0,MIN(1,X11)) -> 0.89983899 | Z11: =R11*1.25 -> 0.90644789 | AA11: =IF(Inputs!$B$55=0,0,IF(Inputs!$B$55=1,IF(Y11<0.8,0.5,0),IF(AND(Y11<0.85,Z11/(Y11+0.5*(1-Y11))>=0.95),1,0))) -> 0 | AB11: =0.5*(1-Y11) -> 0.050080504 | AC11: =Y11+AA11*AB11 -> 0.89983899 | AD11: =Y11*C11*F11*Inputs!$B$51 -> 2294589.4 | AE11: =Y11*C11*Inputs!$B$8*F11*MIN(1,Z11/MAX(Y11,0.0001))^0.5+AA11*AB11*C11*Inputs!$B$8*F11*MIN(1,Z11/MAX(AC11,0.0001))^0.5 -> 1032565.2 | AF11: =AA11*(AB11*C11*F11*Inputs!$B$51*0.6-0.1*Y11*C11*F11*Inputs!$B$51*0.4) -> 0 | AG11: =Inputs!$B$56*0.175*Y11*C11*(Inputs!$B$9*F11)*0.5*0.7 -> 0 | AH11: =(AD11+AE11+AF11+AG11)*Inputs!$B$19*MIN(Inputs!$B$58,Inputs!$B$18) -> 0 | AI11: =IF(Inputs!$B$57=0,3,IF(Inputs!$B$57=1,IF(MAX(0,MIN(1,X11))>=Inputs!$C$26,2,1),IF(MAX(0,MIN(1,X11))-0.07>=Inputs!$C$27,3,IF(MAX(0,MIN(1,X11))-0.07>=Inputs!$C$26,2,1)))) -> 2 | AJ11: =INDEX(Inputs!$C$25:$C$27,AI11) -> 0.65 | AK11: =IF(Inputs!$B$23="No",0,IF(IF(Inputs!$B$20="Yes",AC11,Y11)>=AJ11,INDEX(Inputs!$B$25:$B$27,AI11)*G11,0)) -> 0 | AL11: =AD11+AE11+AF11+AG11+AH11+AK11 -> 3327154.7 | AM11: =AL11-U11-BB11-BC11 -> 506437.23 | AN11: =AM11/IF(Inputs!$B$17="Planned spend",U11,J11) -> 0.1805622 | AO11: =MIN(1,Z11/MAX(AC11,0.01)) -> 1 | AP11: =MAX(0,MIN(1,1-2*MAX(0,Inputs!$B$51/(0.6+0.6*Q11)-1))) -> 1 | AQ11: =0.09*(1-0.7*Inputs!$B$54) -> 0.0585 | AR11: =MAX(0,MIN(1,0.35*AO11+0.3*Q11+0.08*AP11+0.15*V11-AQ11+Inputs!$B$59*(A11-1)-IF(Inputs!$B$66="Turn down",Inputs!$B$68*IF(Inputs!$B$67="Expected",IF(A11=1,1,Inputs!$B$70),1),0)+SUMPRODUCT(('Scripted events'!$B$5:$B$60=A11)*'Scripted events'!$K$5:$K$60*'Scripted events'!$F$5:$F$60))) -> 0.73174582 | AS11: =MAX(0,MIN(1,0.25+0.4*MAX(0,MIN(1,(Inputs!$B$53-0.8)/0.4))+0.2*MAX(0,MIN(1,R11/0.8))+0.1*AC11+Inputs!$B$59*(A11-1)-IF(Inputs!$B$66="Turn down",Inputs!$B$69*IF(Inputs!$B$67="Expected",IF(A11=1,1,Inputs!$B$70),1),0)+SUMPRODUCT(('Scripted events'!$B$5:$B$60=A11)*'Scripted events'!$K$5:$K$60*'Scripted events'!$G$5:$G$60))) -> 0.75727348 | AT11: =IF(AN11>=Inputs!H43,1,0) -> 1 | AU11: =IF(AR11>=Inputs!F43,1,0) -> 1 | AV11: =IF(AS11>=Inputs!G43,1,0) -> 1 | AW11: =AT11+AU11+AV11 -> 3 | AX11: =IF(AW11>=2,"Pass","Replay") -> Pass | AY11: =IF(AW11=3,Inputs!$B$16,Inputs!$B$15)*I11 -> 151179.38 | AZ11: =MAX(0,J11+AM11-I11-AY11) -> 640601.5 | BA11: =Inputs!$B$22*V11+(1-Inputs!$B$22)*(AR11+AS11)/2+SUMPRODUCT(('Scripted events'!$B$5:$B$60=A11)*'Scripted events'!$K$5:$K$60*'Scripted events'!$H$5:$H$60) -> 0.70993079 | BB11: =IF(Inputs!$B$66="Ignore",IF(Inputs!$B$67="Fined",1,IF(Inputs!$B$67="Not fined",0,Inputs!$B$65*IF(A11=1,1,Inputs!$B$70)))*IF(Inputs!$B$63="Yes",Inputs!$B$64*G11,Inputs!$B$62),0) -> 15937.5 | BC11: =SUMPRODUCT(('Scripted events'!$B$5:$B$60=A11)*'Scripted events'!$K$5:$K$60*'Scripted events'!$E$5:$E$60)*G11 -> 0
A12: =Inputs!A44 -> 8 | B12: =Inputs!B44 -> Logistics | C12: =Inputs!C44 -> 25000 | D12: =Inputs!D44 -> 3 | E12: =Inputs!E44 -> 100 | F12: =E12*(1+Inputs!$B$7*(D12-1)) -> 200 | G12: =C12*F12 -> 5000000 | H12: =AZ11 -> 640601.5 | I12: =IF(Inputs!$B$13="Yes",MAX(0,Inputs!$B$14*G12-H12),0) -> 4859398.5 | J12: =H12+I12 -> 5500000 | K12: =Inputs!$B$49 -> 0.75 | L12: =Inputs!$B$50 -> 0.75 | M12: =Inputs!$B$10*G12*K12^1.5*Inputs!$B$53*(1-0.1*Inputs!$B$52) -> 2650037.7 | N12: =Inputs!$B$11*G12*L12 -> 1125000 | O12: =Inputs!$B$12*G12 -> 1850000 | P12: =IF(M12+N12+O12>J12,MAX(0.15,MIN(1,(J12-O12)/(M12+N12))),1) -> 0.96687775 | Q12: =K12*P12^0.67 -> 0.73326375 | R12: =L12*P12 -> 0.72515831 | S12: =Inputs!$B$10*G12*Q12^1.5*Inputs!$B$53*(1-0.1*Inputs!$B$52) -> 2561831 | T12: =Inputs!$B$11*G12*R12 -> 1087737.5 | U12: =S12+T12+O12 -> 5499568.5 | V12: =BA11 -> 0.70993079 | W12: =MAX(0.3,1-1.1*(Inputs!$B$51/(0.6+0.6*Q12)-1)) -> 1.0422652 | X12: =(0.2+0.8*Q12)*(0.75+0.5*V12)*W12 -> 0.90591393 | Y12: =MAX(0,MIN(1,X12)) -> 0.90591393 | Z12: =R12*1.25 -> 0.90644789 | AA12: =IF(Inputs!$B$55=0,0,IF(Inputs!$B$55=1,IF(Y12<0.8,0.5,0),IF(AND(Y12<0.85,Z12/(Y12+0.5*(1-Y12))>=0.95),1,0))) -> 0 | AB12: =0.5*(1-Y12) -> 0.047043033 | AC12: =Y12+AA12*AB12 -> 0.90591393 | AD12: =Y12*C12*F12*Inputs!$B$51 -> 4529569.7 | AE12: =Y12*C12*Inputs!$B$8*F12*MIN(1,Z12/MAX(Y12,0.0001))^0.5+AA12*AB12*C12*Inputs!$B$8*F12*MIN(1,Z12/MAX(AC12,0.0001))^0.5 -> 2038306.4 | AF12: =AA12*(AB12*C12*F12*Inputs!$B$51*0.6-0.1*Y12*C12*F12*Inputs!$B$51*0.4) -> 0 | AG12: =Inputs!$B$56*0.175*Y12*C12*(Inputs!$B$9*F12)*0.5*0.7 -> 0 | AH12: =(AD12+AE12+AF12+AG12)*Inputs!$B$19*MIN(Inputs!$B$58,Inputs!$B$18) -> 0 | AI12: =IF(Inputs!$B$57=0,3,IF(Inputs!$B$57=1,IF(MAX(0,MIN(1,X12))>=Inputs!$C$26,2,1),IF(MAX(0,MIN(1,X12))-0.07>=Inputs!$C$27,3,IF(MAX(0,MIN(1,X12))-0.07>=Inputs!$C$26,2,1)))) -> 2 | AJ12: =INDEX(Inputs!$C$25:$C$27,AI12) -> 0.65 | AK12: =IF(Inputs!$B$23="No",0,IF(IF(Inputs!$B$20="Yes",AC12,Y12)>=AJ12,INDEX(Inputs!$B$25:$B$27,AI12)*G12,0)) -> 0 | AL12: =AD12+AE12+AF12+AG12+AH12+AK12 -> 6567876 | AM12: =AL12-U12-BB12-BC12 -> 1037057.5 | AN12: =AM12/IF(Inputs!$B$17="Planned spend",U12,J12) -> 0.18857071 | AO12: =MIN(1,Z12/MAX(AC12,0.01)) -> 1 | AP12: =MAX(0,MIN(1,1-2*MAX(0,Inputs!$B$51/(0.6+0.6*Q12)-1))) -> 1 | AQ12: =0.09*(1-0.7*Inputs!$B$54) -> 0.0585 | AR12: =MAX(0,MIN(1,0.35*AO12+0.3*Q12+0.08*AP12+0.15*V12-AQ12+Inputs!$B$59*(A12-1)-IF(Inputs!$B$66="Turn down",Inputs!$B$68*IF(Inputs!$B$67="Expected",IF(A12=1,1,Inputs!$B$70),1),0)+SUMPRODUCT(('Scripted events'!$B$5:$B$60=A12)*'Scripted events'!$K$5:$K$60*'Scripted events'!$F$5:$F$60))) -> 0.73996874 | AS12: =MAX(0,MIN(1,0.25+0.4*MAX(0,MIN(1,(Inputs!$B$53-0.8)/0.4))+0.2*MAX(0,MIN(1,R12/0.8))+0.1*AC12+Inputs!$B$59*(A12-1)-IF(Inputs!$B$66="Turn down",Inputs!$B$69*IF(Inputs!$B$67="Expected",IF(A12=1,1,Inputs!$B$70),1),0)+SUMPRODUCT(('Scripted events'!$B$5:$B$60=A12)*'Scripted events'!$K$5:$K$60*'Scripted events'!$G$5:$G$60))) -> 0.76388097 | AT12: =IF(AN12>=Inputs!H44,1,0) -> 1 | AU12: =IF(AR12>=Inputs!F44,1,0) -> 1 | AV12: =IF(AS12>=Inputs!G44,1,0) -> 1 | AW12: =AT12+AU12+AV12 -> 3 | AX12: =IF(AW12>=2,"Pass","Replay") -> Pass | AY12: =IF(AW12=3,Inputs!$B$16,Inputs!$B$15)*I12 -> 291563.91 | AZ12: =MAX(0,J12+AM12-I12-AY12) -> 1386095.1 | BA12: =Inputs!$B$22*V12+(1-Inputs!$B$22)*(AR12+AS12)/2+SUMPRODUCT(('Scripted events'!$B$5:$B$60=A12)*'Scripted events'!$K$5:$K$60*'Scripted events'!$H$5:$H$60) -> 0.72252901 | BB12: =IF(Inputs!$B$66="Ignore",IF(Inputs!$B$67="Fined",1,IF(Inputs!$B$67="Not fined",0,Inputs!$B$65*IF(A12=1,1,Inputs!$B$70)))*IF(Inputs!$B$63="Yes",Inputs!$B$64*G12,Inputs!$B$62),0) -> 31250 | BC12: =SUMPRODUCT(('Scripted events'!$B$5:$B$60=A12)*'Scripted events'!$K$5:$K$60*'Scripted events'!$E$5:$E$60)*G12 -> 0
A13: =Inputs!A45 -> 9 | B13: =Inputs!B45 -> The Council | C13: =Inputs!C45 -> 30000 | D13: =Inputs!D45 -> 3 | E13: =Inputs!E45 -> 110 | F13: =E13*(1+Inputs!$B$7*(D13-1)) -> 220 | G13: =C13*F13 -> 6600000 | H13: =AZ12 -> 1386095.1 | I13: =IF(Inputs!$B$13="Yes",MAX(0,Inputs!$B$14*G13-H13),0) -> 5873904.9 | J13: =H13+I13 -> 7260000 | K13: =Inputs!$B$49 -> 0.75 | L13: =Inputs!$B$50 -> 0.75 | M13: =Inputs!$B$10*G13*K13^1.5*Inputs!$B$53*(1-0.1*Inputs!$B$52) -> 3498049.8 | N13: =Inputs!$B$11*G13*L13 -> 1485000 | O13: =Inputs!$B$12*G13 -> 2442000 | P13: =IF(M13+N13+O13>J13,MAX(0.15,MIN(1,(J13-O13)/(M13+N13))),1) -> 0.96687775 | Q13: =K13*P13^0.67 -> 0.73326375 | R13: =L13*P13 -> 0.72515831 | S13: =Inputs!$B$10*G13*Q13^1.5*Inputs!$B$53*(1-0.1*Inputs!$B$52) -> 3381617 | T13: =Inputs!$B$11*G13*R13 -> 1435813.5 | U13: =S13+T13+O13 -> 7259430.4 | V13: =BA12 -> 0.72252901 | W13: =MAX(0.3,1-1.1*(Inputs!$B$51/(0.6+0.6*Q13)-1)) -> 1.0422652 | X13: =(0.2+0.8*Q13)*(0.75+0.5*V13)*W13 -> 0.91107831 | Y13: =MAX(0,MIN(1,X13)) -> 0.91107831 | Z13: =R13*1.25 -> 0.90644789 | AA13: =IF(Inputs!$B$55=0,0,IF(Inputs!$B$55=1,IF(Y13<0.8,0.5,0),IF(AND(Y13<0.85,Z13/(Y13+0.5*(1-Y13))>=0.95),1,0))) -> 0 | AB13: =0.5*(1-Y13) -> 0.044460847 | AC13: =Y13+AA13*AB13 -> 0.91107831 | AD13: =Y13*C13*F13*Inputs!$B$51 -> 6013116.8 | AE13: =Y13*C13*Inputs!$B$8*F13*MIN(1,Z13/MAX(Y13,0.0001))^0.5+AA13*AB13*C13*Inputs!$B$8*F13*MIN(1,Z13/MAX(AC13,0.0001))^0.5 -> 2699017.6 | AF13: =AA13*(AB13*C13*F13*Inputs!$B$51*0.6-0.1*Y13*C13*F13*Inputs!$B$51*0.4) -> 0 | AG13: =Inputs!$B$56*0.175*Y13*C13*(Inputs!$B$9*F13)*0.5*0.7 -> 0 | AH13: =(AD13+AE13+AF13+AG13)*Inputs!$B$19*MIN(Inputs!$B$58,Inputs!$B$18) -> 0 | AI13: =IF(Inputs!$B$57=0,3,IF(Inputs!$B$57=1,IF(MAX(0,MIN(1,X13))>=Inputs!$C$26,2,1),IF(MAX(0,MIN(1,X13))-0.07>=Inputs!$C$27,3,IF(MAX(0,MIN(1,X13))-0.07>=Inputs!$C$26,2,1)))) -> 2 | AJ13: =INDEX(Inputs!$C$25:$C$27,AI13) -> 0.65 | AK13: =IF(Inputs!$B$23="No",0,IF(IF(Inputs!$B$20="Yes",AC13,Y13)>=AJ13,INDEX(Inputs!$B$25:$B$27,AI13)*G13,0)) -> 0 | AL13: =AD13+AE13+AF13+AG13+AH13+AK13 -> 8712134.5 | AM13: =AL13-U13-BB13-BC13 -> 1411454 | AN13: =AM13/IF(Inputs!$B$17="Planned spend",U13,J13) -> 0.19443041 | AO13: =MIN(1,Z13/MAX(AC13,0.01)) -> 0.99491766 | AP13: =MAX(0,MIN(1,1-2*MAX(0,Inputs!$B$51/(0.6+0.6*Q13)-1))) -> 1 | AQ13: =0.09*(1-0.7*Inputs!$B$54) -> 0.0585 | AR13: =MAX(0,MIN(1,0.35*AO13+0.3*Q13+0.08*AP13+0.15*V13-AQ13+Inputs!$B$59*(A13-1)-IF(Inputs!$B$66="Turn down",Inputs!$B$68*IF(Inputs!$B$67="Expected",IF(A13=1,1,Inputs!$B$70),1),0)+SUMPRODUCT(('Scripted events'!$B$5:$B$60=A13)*'Scripted events'!$K$5:$K$60*'Scripted events'!$F$5:$F$60))) -> 0.74607966 | AS13: =MAX(0,MIN(1,0.25+0.4*MAX(0,MIN(1,(Inputs!$B$53-0.8)/0.4))+0.2*MAX(0,MIN(1,R13/0.8))+0.1*AC13+Inputs!$B$59*(A13-1)-IF(Inputs!$B$66="Turn down",Inputs!$B$69*IF(Inputs!$B$67="Expected",IF(A13=1,1,Inputs!$B$70),1),0)+SUMPRODUCT(('Scripted events'!$B$5:$B$60=A13)*'Scripted events'!$K$5:$K$60*'Scripted events'!$G$5:$G$60))) -> 0.77039741 | AT13: =IF(AN13>=Inputs!H45,1,0) -> 1 | AU13: =IF(AR13>=Inputs!F45,1,0) -> 0 | AV13: =IF(AS13>=Inputs!G45,1,0) -> 1 | AW13: =AT13+AU13+AV13 -> 2 | AX13: =IF(AW13>=2,"Pass","Replay") -> Pass | AY13: =IF(AW13=3,Inputs!$B$16,Inputs!$B$15)*I13 -> 704868.59 | AZ13: =MAX(0,J13+AM13-I13-AY13) -> 2092680.5 | BA13: =Inputs!$B$22*V13+(1-Inputs!$B$22)*(AR13+AS13)/2+SUMPRODUCT(('Scripted events'!$B$5:$B$60=A13)*'Scripted events'!$K$5:$K$60*'Scripted events'!$H$5:$H$60) -> 0.73324187 | BB13: =IF(Inputs!$B$66="Ignore",IF(Inputs!$B$67="Fined",1,IF(Inputs!$B$67="Not fined",0,Inputs!$B$65*IF(A13=1,1,Inputs!$B$70)))*IF(Inputs!$B$63="Yes",Inputs!$B$64*G13,Inputs!$B$62),0) -> 41250 | BC13: =SUMPRODUCT(('Scripted events'!$B$5:$B$60=A13)*'Scripted events'!$K$5:$K$60*'Scripted events'!$E$5:$E$60)*G13 -> 0
A14: =Inputs!A46 -> 10 | B14: =Inputs!B46 -> Flagship | C14: =Inputs!C46 -> 50000 | D14: =Inputs!D46 -> 4 | E14: =Inputs!E46 -> 130 | F14: =E14*(1+Inputs!$B$7*(D14-1)) -> 325 | G14: =C14*F14 -> 16250000 | H14: =AZ13 -> 2092680.5 | I14: =IF(Inputs!$B$13="Yes",MAX(0,Inputs!$B$14*G14-H14),0) -> 15782319 | J14: =H14+I14 -> 17875000 | K14: =Inputs!$B$49 -> 0.75 | L14: =Inputs!$B$50 -> 0.75 | M14: =Inputs!$B$10*G14*K14^1.5*Inputs!$B$53*(1-0.1*Inputs!$B$52) -> 8612622.6 | N14: =Inputs!$B$11*G14*L14 -> 3656250 | O14: =Inputs!$B$12*G14 -> 6012500 | P14: =IF(M14+N14+O14>J14,MAX(0.15,MIN(1,(J14-O14)/(M14+N14))),1) -> 0.96687775 | Q14: =K14*P14^0.67 -> 0.73326375 | R14: =L14*P14 -> 0.72515831 | S14: =Inputs!$B$10*G14*Q14^1.5*Inputs!$B$53*(1-0.1*Inputs!$B$52) -> 8325950.9 | T14: =Inputs!$B$11*G14*R14 -> 3535146.8 | U14: =S14+T14+O14 -> 17873598 | V14: =BA13 -> 0.73324187 | W14: =MAX(0.3,1-1.1*(Inputs!$B$51/(0.6+0.6*Q14)-1)) -> 1.0422652 | X14: =(0.2+0.8*Q14)*(0.75+0.5*V14)*W14 -> 0.91546981 | Y14: =MAX(0,MIN(1,X14)) -> 0.91546981 | Z14: =R14*1.25 -> 0.90644789 | AA14: =IF(Inputs!$B$55=0,0,IF(Inputs!$B$55=1,IF(Y14<0.8,0.5,0),IF(AND(Y14<0.85,Z14/(Y14+0.5*(1-Y14))>=0.95),1,0))) -> 0 | AB14: =0.5*(1-Y14) -> 0.042265094 | AC14: =Y14+AA14*AB14 -> 0.91546981 | AD14: =Y14*C14*F14*Inputs!$B$51 -> 14876384 | AE14: =Y14*C14*Inputs!$B$8*F14*MIN(1,Z14/MAX(Y14,0.0001))^0.5+AA14*AB14*C14*Inputs!$B$8*F14*MIN(1,Z14/MAX(AC14,0.0001))^0.5 -> 6661304.9 | AF14: =AA14*(AB14*C14*F14*Inputs!$B$51*0.6-0.1*Y14*C14*F14*Inputs!$B$51*0.4) -> 0 | AG14: =Inputs!$B$56*0.175*Y14*C14*(Inputs!$B$9*F14)*0.5*0.7 -> 0 | AH14: =(AD14+AE14+AF14+AG14)*Inputs!$B$19*MIN(Inputs!$B$58,Inputs!$B$18) -> 0 | AI14: =IF(Inputs!$B$57=0,3,IF(Inputs!$B$57=1,IF(MAX(0,MIN(1,X14))>=Inputs!$C$26,2,1),IF(MAX(0,MIN(1,X14))-0.07>=Inputs!$C$27,3,IF(MAX(0,MIN(1,X14))-0.07>=Inputs!$C$26,2,1)))) -> 2 | AJ14: =INDEX(Inputs!$C$25:$C$27,AI14) -> 0.65 | AK14: =IF(Inputs!$B$23="No",0,IF(IF(Inputs!$B$20="Yes",AC14,Y14)>=AJ14,INDEX(Inputs!$B$25:$B$27,AI14)*G14,0)) -> 0 | AL14: =AD14+AE14+AF14+AG14+AH14+AK14 -> 21537689 | AM14: =AL14-U14-BB14-BC14 -> 3562529.2 | AN14: =AM14/IF(Inputs!$B$17="Planned spend",U14,J14) -> 0.19931797 | AO14: =MIN(1,Z14/MAX(AC14,0.01)) -> 0.99014504 | AP14: =MAX(0,MIN(1,1-2*MAX(0,Inputs!$B$51/(0.6+0.6*Q14)-1))) -> 1 | AQ14: =0.09*(1-0.7*Inputs!$B$54) -> 0.0585 | AR14: =MAX(0,MIN(1,0.35*AO14+0.3*Q14+0.08*AP14+0.15*V14-AQ14+Inputs!$B$59*(A14-1)-IF(Inputs!$B$66="Turn down",Inputs!$B$68*IF(Inputs!$B$67="Expected",IF(A14=1,1,Inputs!$B$70),1),0)+SUMPRODUCT(('Scripted events'!$B$5:$B$60=A14)*'Scripted events'!$K$5:$K$60*'Scripted events'!$F$5:$F$60))) -> 0.75201617 | AS14: =MAX(0,MIN(1,0.25+0.4*MAX(0,MIN(1,(Inputs!$B$53-0.8)/0.4))+0.2*MAX(0,MIN(1,R14/0.8))+0.1*AC14+Inputs!$B$59*(A14-1)-IF(Inputs!$B$66="Turn down",Inputs!$B$69*IF(Inputs!$B$67="Expected",IF(A14=1,1,Inputs!$B$70),1),0)+SUMPRODUCT(('Scripted events'!$B$5:$B$60=A14)*'Scripted events'!$K$5:$K$60*'Scripted events'!$G$5:$G$60))) -> 0.77683656 | AT14: =IF(AN14>=Inputs!H46,1,0) -> 0 | AU14: =IF(AR14>=Inputs!F46,1,0) -> 0 | AV14: =IF(AS14>=Inputs!G46,1,0) -> 1 | AW14: =AT14+AU14+AV14 -> 1 | AX14: =IF(AW14>=2,"Pass","Replay") -> Replay | AY14: =IF(AW14=3,Inputs!$B$16,Inputs!$B$15)*I14 -> 1893878.3 | AZ14: =MAX(0,J14+AM14-I14-AY14) -> 3761331.4 | BA14: =Inputs!$B$22*V14+(1-Inputs!$B$22)*(AR14+AS14)/2+SUMPRODUCT(('Scripted events'!$B$5:$B$60=A14)*'Scripted events'!$K$5:$K$60*'Scripted events'!$H$5:$H$60) -> 0.74259722 | BB14: =IF(Inputs!$B$66="Ignore",IF(Inputs!$B$67="Fined",1,IF(Inputs!$B$67="Not fined",0,Inputs!$B$65*IF(A14=1,1,Inputs!$B$70)))*IF(Inputs!$B$63="Yes",Inputs!$B$64*G14,Inputs!$B$62),0) -> 101562.5 | BC14: =SUMPRODUCT(('Scripted events'!$B$5:$B$60=A14)*'Scripted events'!$K$5:$K$60*'Scripted events'!$E$5:$E$60)*G14 -> 0

Sheet Notes
A1: What this is | B1: A formula-driven version of the economy model used in the earlier simulations. It uses expected values (no randomness, no replays), so results are smoother than the Monte Carlo runs.
A2: What is invented | B2: Every coefficient (costs, spend per head, satisfaction weights, sponsor tiers, player types) is an illustrative guess. Replace them with real numbers as the design firms up.
A3: Replays | B3: A festival with fewer than 2 stars shows Replay, but the sheet carries cash and reputation on as if it had passed. Use it to see where each player type would get stuck.
A4: Promoter advance | B4: If on, the budget is topped up to the chosen multiple of full-scale ticket revenue and repaid after the festival with the fee. Turn it off to see why carried-over cash alone cannot fund the ladder.
A5: Squeeze factor | B5: If the budget cannot cover the planned lineup and facilities, quality is scaled down. This is how a funding gap shows up.
A6: Satisfaction | B6: Customer: queues against facility capacity, lineup quality, fair pricing, reputation, one average event, HQ upgrade bonus. Band: fee generosity, facilities, crowd size, HQ bonus.
A7: Defaults | B7: The defaults describe the MVP: no sponsorship, no rewarded ads and overhead 0.37. The earlier Monte Carlo runs had sponsorship on and overhead 0.50, which made the profit star depend on sponsor money. Without sponsors, the profit star was out of reach at festivals 1 to 5 until overhead came down to about 0.37; below 0.35 the game becomes too easy.
A8: Ticket price | B8: The player sets the price. Attendance depends on the price against the perceived value of the lineup: perceived value = fair price x (0.6 + 0.6 x lineup quality), so a weak lineup at a high price pulls fewer people.
A9: Noise complaint | B9: One possible complaint per festival. Ignore it and risk a fine (25% chance); turn the band down and lose some customer and band satisfaction. The default scales the fine to 5% of full-scale ticket revenue (about £625 at festival 1, £2,250 at festival 2, £6,000 at festival 3), because a flat £5,000 is 40% of festival 1 revenue but trivial by festival 8.
A10: Not modelled | B10: Negotiation outcomes, band growth, weather, the stuck-player assist and mentor tips, random events beyond one average event.

Sheet Scripted events
A1: Events: decisions and consequences
A2: Pick an option for each event in the Choices table (blue). Costs are a share of full-scale ticket revenue so they scale with the festival (a negative cost is a net gain, as with merch). Satisfaction and reputation changes are in points (0.05 = 5 points). Random events use their chance in the Expected view, or all happen in the All happen view. The noise complaint is on the Inputs sheet.
A3: Random events view | B3: Expected
A4: Event | B4: Festival | C4: Option | D4: What the player does | E4: Cost (share of full-scale ticket revenue) | F4: Customer satisfaction change | G4: Band satisfaction change | H4: Reputation change | I4: Selected (1 = yes) | J4: Chance it happens | K4: Weight used
A5: Food stall queue | B5: 1 | C5: A | D5: Add an emergency food stall (1.5 times the usual price) | E5: 0.036 | F5: 0 | G5: 0 | H5: 0 | I5: =IF(INDEX($B$44:$B$53,MATCH(A5,$A$44:$A$53,0))=C5,1,0) -> 1 | J5: 1 | K5: =I5*IF($B$3="All happen",1,J5) -> 1
A6: Food stall queue | B6: 1 | C6: B | D6: Open a free water and snacks point | E6: 0.005 | F6: -0.02 | G6: 0 | H6: 0 | I6: =IF(INDEX($B$44:$B$53,MATCH(A6,$A$44:$A$53,0))=C6,1,0) -> 0 | J6: 1 | K6: =I6*IF($B$3="All happen",1,J6) -> 0
A7: Food stall queue | B7: 1 | C7: C | D7: Do nothing | E7: 0 | F7: -0.05 | G7: 0 | H7: 0 | I7: =IF(INDEX($B$44:$B$53,MATCH(A7,$A$44:$A$53,0))=C7,1,0) -> 0 | J7: 1 | K7: =I7*IF($B$3="All happen",1,J7) -> 0
A8: Band running late | B8: 1 | C8: A | D8: Stretch the opener's set (overtime) | E8: 0.005 | F8: 0 | G8: 0 | H8: 0 | I8: =IF(INDEX($B$44:$B$53,MATCH(A8,$A$44:$A$53,0))=C8,1,0) -> 1 | J8: 1 | K8: =I8*IF($B$3="All happen",1,J8) -> 1
A9: Band running late | B9: 1 | C9: B | D9: Play music over the speakers | E9: 0 | F9: -0.03 | G9: 0 | H9: 0 | I9: =IF(INDEX($B$44:$B$53,MATCH(A9,$A$44:$A$53,0))=C9,1,0) -> 0 | J9: 1 | K9: =I9*IF($B$3="All happen",1,J9) -> 0
A10: Band running late | B10: 1 | C10: C | D10: Cut the late band's set short | E10: 0 | F10: -0.01 | G10: -0.05 | H10: 0 | I10: =IF(INDEX($B$44:$B$53,MATCH(A10,$A$44:$A$53,0))=C10,1,0) -> 0 | J10: 1 | K10: =I10*IF($B$3="All happen",1,J10) -> 0
A11: Stage equipment breaks | B11: 2 | C11: A | D11: Hire a replacement | E11: 0.03 | F11: 0 | G11: 0 | H11: 0 | I11: =IF(INDEX($B$44:$B$53,MATCH(A11,$A$44:$A$53,0))=C11,1,0) -> 1 | J11: 1 | K11: =I11*IF($B$3="All happen",1,J11) -> 1
A12: Stage equipment breaks | B12: 2 | C12: B | D12: Borrow kit from another band | E12: 0 | F12: 0 | G12: -0.04 | H12: 0 | I12: =IF(INDEX($B$44:$B$53,MATCH(A12,$A$44:$A$53,0))=C12,1,0) -> 0 | J12: 1 | K12: =I12*IF($B$3="All happen",1,J12) -> 0
A13: Stage equipment breaks | B13: 2 | C13: C | D13: Play on without it | E13: 0 | F13: -0.04 | G13: -0.04 | H13: 0 | I13: =IF(INDEX($B$44:$B$53,MATCH(A13,$A$44:$A$53,0))=C13,1,0) -> 0 | J13: 1 | K13: =I13*IF($B$3="All happen",1,J13) -> 0
A14: Headliner storms off | B14: 3 | C14: A | D14: Talk them back on (bonus of about 15% of their fee) | E14: 0.01875 | F14: 0 | G14: -0.03 | H14: 0 | I14: =IF(INDEX($B$44:$B$53,MATCH(A14,$A$44:$A$53,0))=C14,1,0) -> 1 | J14: 1 | K14: =I14*IF($B$3="All happen",1,J14) -> 1
A15: Headliner storms off | B15: 3 | C15: B | D15: Bring the support act back on | E15: 0 | F15: -0.05 | G15: 0 | H15: 0 | I15: =IF(INDEX($B$44:$B$53,MATCH(A15,$A$44:$A$53,0))=C15,1,0) -> 0 | J15: 1 | K15: =I15*IF($B$3="All happen",1,J15) -> 0
A16: Headliner storms off | B16: 3 | C16: C | D16: Do nothing | E16: 0 | F16: -0.1 | G16: 0 | H16: -0.05 | I16: =IF(INDEX($B$44:$B$53,MATCH(A16,$A$44:$A$53,0))=C16,1,0) -> 0 | J16: 1 | K16: =I16*IF($B$3="All happen",1,J16) -> 0
... A40: Merch selling fast | B40: 3 | C40: C | D40: Let it sell out | E40: 0 | F40: -0.01 | G40: 0 | H40: 0 | I40: =IF(INDEX($B$44:$B$53,MATCH(A40,$A$44:$A$53,0))=C40,1,0) -> 0 | J40: 0.5 | K40: =I40*IF($B$3="All happen",1,J40) -> 0
A42: Choices
A43: Event | B43: Option chosen (A, B or C)
A44: Food stall queue | B44: A
A45: Band running late | B45: A
A46: Stage equipment breaks | B46: A
A47: Headliner storms off | B47: A
A48: Light rain | B48: A
A49: Headliner delayed | B49: A
A50: Band pulls out | B50: A
A51: Sound bleed | B51: A
A52: Toilets out of order | B52: A
A53: Merch selling fast | B53: A
A55: Pay-to-fix (A) costs at festivals 2 and 3 are 1.5 times the first draft, so paying for everything is no longer free. Not yet modelled: fair pay and good backstage halving the headliner penalties.

Sheet Facility costs
A1: Facility unit costs, aligned with the economy model
A2: Full facilities (enough for the whole crowd plus 25% headroom) cost the facilities coefficient x full-scale ticket revenue. Each unit serves 100 people. Change the number of facility types (blue) per festival.
A4: # | B4: Festival | C4: Ticket price for the festival (£) | D4: Facility types in play | E4: Cost per person served, all types (£) | F4: Cost per unit, each serving 100 people (£) | G4: Full set for the whole crowd (£)
A5: =Model!A5 -> 1 | B5: =Model!B5 -> Village Green | C5: =Model!F5 -> 25 | D5: 2 | E5: =Inputs!$B$11*C5/1.25 -> 6 | F5: =E5*100/D5 -> 300 | G5: =Inputs!$B$11*Model!G5 -> 3750
A6: =Model!A6 -> 2 | B6: =Model!B6 -> The Local Field | C6: =Model!F6 -> 30 | D6: 3 | E6: =Inputs!$B$11*C6/1.25 -> 7.2 | F6: =E6*100/D6 -> 240 | G6: =Inputs!$B$11*Model!G6 -> 13500
A7: =Model!A7 -> 3 | B7: =Model!B7 -> Two Stages | C7: =Model!F7 -> 40 | D7: 3 | E7: =Inputs!$B$11*C7/1.25 -> 9.6 | F7: =E7*100/D7 -> 320 | G7: =Inputs!$B$11*Model!G7 -> 36000
A8: =Model!A8 -> 4 | B8: =Model!B8 -> First Overnight | C8: =Model!F8 -> 82.5 | D8: 5 | E8: =Inputs!$B$11*C8/1.25 -> 19.8 | F8: =E8*100/D8 -> 396 | G8: =Inputs!$B$11*Model!G8 -> 123750
A9: =Model!A9 -> 5 | B9: =Model!B9 -> Themed Weekend | C9: =Model!F9 -> 82.5 | D9: 6 | E9: =Inputs!$B$11*C9/1.25 -> 19.8 | F9: =E9*100/D9 -> 330 | G9: =Inputs!$B$11*Model!G9 -> 123750
A10: =Model!A10 -> 6 | B10: =Model!B10 -> Growing Up | C10: =Model!F10 -> 140 | D10: 7 | E10: =Inputs!$B$11*C10/1.25 -> 33.6 | F10: =E10*100/D10 -> 480 | G10: =Inputs!$B$11*Model!G10 -> 420000
A11: =Model!A11 -> 7 | B11: =Model!B11 -> The Big Booking | C11: =Model!F11 -> 170 | D11: 7 | E11: =Inputs!$B$11*C11/1.25 -> 40.8 | F11: =E11*100/D11 -> 582.85714 | G11: =Inputs!$B$11*Model!G11 -> 765000
A12: =Model!A12 -> 8 | B12: =Model!B12 -> Logistics | C12: =Model!F12 -> 200 | D12: 8 | E12: =Inputs!$B$11*C12/1.25 -> 48 | F12: =E12*100/D12 -> 600 | G12: =Inputs!$B$11*Model!G12 -> 1500000
A13: =Model!A13 -> 9 | B13: =Model!B13 -> The Council | C13: =Model!F13 -> 220 | D13: 8 | E13: =Inputs!$B$11*C13/1.25 -> 52.8 | F13: =E13*100/D13 -> 660 | G13: =Inputs!$B$11*Model!G13 -> 1980000
A14: =Model!A14 -> 10 | B14: =Model!B14 -> Flagship | C14: =Model!F14 -> 325 | D14: 8 | E14: =Inputs!$B$11*C14/1.25 -> 78 | F14: =E14*100/D14 -> 975 | G14: =Inputs!$B$11*Model!G14 -> 4875000
A16: Types assumed: festival 1 toilets and food; festivals 2 and 3 add the bar; later festivals add camping, showers, security and more (guesses to tune).
